File: Calibration/Cernox_calibration.dat
[Header]
TITLE,default name
FILEOPENTIME,1636879688.00,11/14/2021,10:48 AM
BYAPP,Resistivity,2.0,1.0
INFO,BRT Module,BRT_MODULE_NAME
INFO,3101-225 D0,BRT_HW_VERSION
INFO,BRT Module 01.03.04,BRT_SOFTWARE_VERSION
INFO,BRT282,BRT_SERIAL_NUMBER
INFO,cernox,Sample1 Name
INFO,1,Sample1 Cross Section
INFO,1,Sample1 Length
INFO,Ohm,Sample1 Units
INFO,,Sample2 Name
INFO,1,Sample2 Cross Section
INFO,1,Sample2 Length
INFO,Ohm-m,Sample2 Units
INFO,,Sample3 Name
INFO,1,Sample3 Cross Section
INFO,1,Sample3 Length
INFO,Ohm-m,Sample3 Units
INFO,,Sample4 Name
INFO,1,Sample4 Cross Section
INFO,1,Sample4 Length
INFO,Ohm-m,Sample4 Units
FIELDGROUP,Resistivity,2,3,4,5,6,7,8,9,10,11,12,13,14,15,16,17,18,19,20,21,22,23,24,25,26,27,28,29,30,31,32,33,34,35,36,37,38,39,40,41
STARTUPGROUP,Resistivity
STARTUPAXIS,X,2,LINEAR,AUTO
STARTUPAXIS,Y1,7,LINEAR,AUTO
STARTUPAXIS,Y2,9,LINEAR,AUTO
STARTUPAXIS,Y3,11,LINEAR,AUTO
PLOT_APPEARANCE,ALL,HORZ_GRID_ON,VERT_GRID_ON,MARKERS_AND_LINES,ALL_LINES
DATATYPE,TIME,2
DATATYPE,COMMENT,1
[Data]
Comment,Time Stamp (sec),Status (code),Temperature (K),Magnetic Field (Oe),Sample Position (degrees),Bridge 1 Resistivity (Ohm),Bridge 1 Excitation (uA),Bridge 2 Resistivity (Ohm-m),Bridge 2 Excitation (uA),Bridge 3 Resistivity (Ohm-m),Bridge 3 Excitation (uA),Bridge 4 Resistivity (Ohm-m),Bridge 4 Excitation (uA),Bridge 1 Std. Dev. (Ohm),Bridge 2 Std. Dev. (Ohm-m),Bridge 3 Std. Dev. (Ohm-m),Bridge 4 Std. Dev. (Ohm-m),Number of Readings,Bridge 1 Resistance (Ohms),Bridge 2 Resistance (Ohms),Bridge 3 Resistance (Ohms),Bridge 4 Resistance (Ohms)
,27514391.172,,300.001297607422,-0.145506376922131,0,81.0635736083984,1.99990558624268,,,,,,,0.00727188529246137,,,,25,81.0635736083984,,,
,27514688.781,,278.92716796875,-0.398875693082809,0,86.0875045776367,1.99990558624268,,,,,,,0.00661663213208244,,,,25,86.0875045776367,,,
,27514948.984,,259.253229980469,-0.508186445236206,0,91.5834732055664,1.99990558624268,,,,,,,0.0093356237328534,,,,25,91.5834732055664,,,
,27515207.797,,240.968284912109,-0.405390902757645,0,97.4765948486328,1.99990558624268,,,,,,,0.0100544441756994,,,,25,97.4765948486328,,,
,27515463.156,,223.967146606445,-0.268571474552155,0,103.796452331543,1.99990558624268,,,,,,,0.00651402129964483,,,,25,103.796452331543,,,
,27515716.031,,208.168659667969,-0.280877981185913,0,110.536156311035,1.99990558624268,,,,,,,0.00925538374058602,,,,25,110.536156311035,,,
,27515958.172,,193.483121337891,-0.295356231927872,0,117.711929016113,1.99990558624268,,,,,,,0.00691829661614048,,,,25,117.711929016113,,,
,27516192.187,,179.837614746094,-0.3634039914608,0,125.352078552246,1.99990558624268,,,,,,,0.00931621503005805,,,,25,125.352078552246,,,
,27516415.672,,167.15346862793,-0.374262681007385,0,133.416947021484,1.99990558624268,,,,,,,0.00879178278270706,,,,25,133.416947021484,,,
,27516631.656,,155.358583374023,-0.395256131887436,0,142.016070556641,1.99990558624268,,,,,,,0.00932411061377491,,,,25,142.016070556641,,,
,27516838.203,,144.401046142578,-0.420593062639236,0,151.078886108398,1.99990558624268,,,,,,,0.0109274674894138,,,,25,151.078886108398,,,
,27517035.812,,134.210193481445,-0.406114819049835,0,160.68499206543,1.99990558624268,,,,,,,0.00904761816243293,,,,25,160.68499206543,,,
,27517225.766,,124.740456848145,-0.41190612077713,0,170.803991699219,1.99990558624268,,,,,,,0.0103303375404052,,,,25,170.803991699219,,,
,27517411.531,,115.936872253418,-0.187493290603161,0,181.522044067383,1.99990558624268,,,,,,,0.0123733450178869,,,,25,181.522044067383,,,
,27517588.922,,107.75576385498,-0.341686623096466,0,192.846292114258,1.99990558624268,,,,,,,0.0113503437329418,,,,25,192.846292114258,,,
,27517760.328,,100.151563110352,-0.450997376441956,0,204.746533813477,1.99990558624268,,,,,,,0.0138749824257305,,,,25,204.746533813477,,,
,27517925.937,,93.0812380981445,-0.306938831806183,0,217.231585693359,1.99990558624268,,,,,,,0.012527067965696,,,,25,217.231585693359,,,
,27518086.234,,86.5080340576172,-0.332275766134262,0,230.444010009766,1.99990558624268,,,,,,,0.0161489487944621,,,,25,230.444010009766,,,
,27518241.609,,80.3987509155273,-0.332999668121338,0,244.392841186523,1.99990558624268,,,,,,,0.017832882907897,,,,25,244.392841186523,,,
,27518392.984,,74.721145324707,-0.339514887332916,0,259.119849853516,1.99990558624268,,,,,,,0.0136919124898429,,,,25,259.119849853516,,,
,27518538.234,,69.4445123291016,-0.214278049468994,0,274.637583007813,1.99990558624268,,,,,,,0.0115697755679758,,,,25,274.637583007813,,,
,27518679.297,,64.54318359375,-0.173015044331551,0,290.994365234375,1.99990558624268,,,,,,,0.0102189915723547,,,,25,290.994365234375,,,
,27518814.094,,59.9868132019043,-0.129580304026604,0,308.251546630859,1.99990558624268,,,,,,,0.00857786826359041,,,,25,308.251546630859,,,
,27518944.812,,55.752315826416,-0.130304217338562,0,326.486749267578,1.99990558624268,,,,,,,0.00993262637478024,,,,25,326.486749267578,,,
,27519070.922,,51.8179489135742,-0.0253369314968586,0,345.667994384766,1.99990558624268,,,,,,,0.00821448267872389,,,,25,345.667994384766,,,
,27519189.312,,48.1614506530762,0.017373895868659,0,365.908792724609,1.99990558624268,,,,,,,0.00897248585455742,,,,25,365.908792724609,,,
,27519297.797,,44.7638607788086,0.0854216529428959,0,387.218244628906,1.99990558624268,,,,,,,0.0131813539704024,,,,25,387.218244628906,,,
,27519399.422,,41.5989045715332,0.0904890394210815,0,409.753762207031,1.99990558624268,,,,,,,0.0148287542884667,,,,25,409.753762207031,,,
,27519495.156,,38.6641325378418,0.0282325807213783,0,433.394176025391,1.99990558624268,,,,,,,0.0306917807106002,,,,25,433.394176025391,,,
,27519617.047,,35.9199467468262,0.0282325808703899,0,458.508133544922,1.99990558624268,,,,,,,0.00802655817165039,,,,25,458.508133544922,,,
,27519735.484,,33.3850294494629,0.0318521424382925,0,484.757332763672,1.99990558624268,,,,,,,0.00744309513195558,,,,25,484.757332763672,,,
,27519853.297,,31.0294390869141,0.0311282299458981,0,512.289836425781,1.99990558624268,,,,,,,0.0065355773355181,,,,25,512.289836425781,,,
,27519969.109,,28.8405210113525,0.0115825974941254,0,541.241772460937,1.99990558624268,,,,,,,0.0106898898762619,,,,25,541.241772460937,,,
,27520083.25,,26.8067633056641,0.0231651944667101,0,571.681489257812,1.99990558624268,,,,,,,0.00678777331253989,,,,25,571.681489257812,,,
,27520221.25,,24.9215808105469,-0.00651521116495132,0,603.558090820312,1.99990558624268,,,,,,,0.00632657162268083,,,,25,603.558090820312,,,
,27520338,,23.1635151672363,-0.0159260714799166,0,637.329138183594,1.99990558624268,,,,,,,0.00800485294592892,,,,25,637.329138183594,,,
,27520446.422,,21.528722076416,-0.00941086038947105,0,672.863303222656,1.99990558624268,,,,,,,0.00712654469841614,,,,25,672.863303222656,,,
,27520548.875,,20.0092978668213,-0.0325760547816753,0,710.348833007812,1.99990558624268,,,,,,,0.00677327832526643,,,,25,710.348833007812,,,
,27520648.75,,18.5973783111572,-0.170843307375908,0,749.941013183594,1.99990558624268,,,,,,,0.00959606185629207,,,,25,749.941013183594,,,
,27520743.234,,17.285113067627,-0.187493291199207,0,791.786384277344,1.99990558624268,,,,,,,0.00670283885658511,,,,25,791.786384277344,,,
,27520835.156,,16.065174407959,-0.15853679805994,0,836.166943359375,1.99990558624268,,,,,,,0.00771618119247906,,,,25,836.166943359375,,,
,27520925.422,,14.9313697814941,-0.150573762357235,0,883.345971679688,1.99990558624268,,,,,,,0.00977829468926719,,,,25,883.345971679688,,,
,27521013.422,,13.8778650665283,-0.132475953400135,0,933.623051757813,1.99990558624268,,,,,,,0.00787284020010904,,,,25,933.623051757813,,,
,27521099.469,,12.8986039733887,-0.144782462865114,0,987.230405273438,1.99990558624268,,,,,,,0.00730938203425189,,,,25,987.230405273438,,,
,27521183.094,,11.9884359359741,-0.193284591138363,0,1044.57225097656,1.99990558624268,,,,,,,0.00722657925371857,,,,25,1044.57225097656,,,
,27521266.047,,11.1424041366577,-0.169395482242107,0,1106.06124511719,1.99990558624268,,,,,,,0.00666512220281929,,,,25,1106.06124511719,,,
,27521347.422,,10.3561616516113,-0.165775922238827,0,1172.28644042969,1.99990558624268,,,,,,,0.00704582743037259,,,,25,1172.28644042969,,,
,27521473.984,,9.6308476638794,-0.159984622299671,0,1242.95293945313,1.99990558624268,,,,,,,0.178179023574932,,,,25,1242.95293945313,,,
,27521562.344,,8.94560070037842,-0.177358518838882,0,1320.67909667969,1.99990558624268,,,,,,,0.0356252729307143,,,,25,1320.67909667969,,,
,27521648.125,,8.312346534729,-0.156365060508251,0,1404.89380859375,1.99990558624268,,,,,,,0.252044395985176,,,,25,1404.89380859375,,,
,27521732.984,,7.72807117462158,-0.206315012574196,0,1495.90383300781,1.99990558624268,,,,,,,0.0181068534691912,,,,25,1495.90383300781,,,
,27521818.844,,7.1855827331543,-0.154193322956562,0,1594.95382324219,1.99990558624268,,,,,,,0.0396431503622968,,,,25,1594.95382324219,,,
,27521903.734,,6.66765405654907,-0.196180240511894,0,1706.77331542969,1.99990558624268,,,,,,,1.73544605177132,,,,25,1706.77331542969,,,
,27521986.203,,6.20609390258789,-0.176634607315063,0,1824.44768066406,1.99990558624268,,,,,,,0.0333076332963071,,,,25,1824.44768066406,,,
,27522067.594,,5.76727745056152,-0.149125935435295,0,1957.122578125,1.99990558624268,,,,,,,0.0228870340694407,,,,25,1957.122578125,,,
,27522149,,5.36021816253662,-0.0977281615138054,0,2103.60700195312,1.99990558624268,,,,,,,0.0523355377929111,,,,25,2103.60700195312,,,
,27522230.5,,4.9819083404541,-0.0608086358010769,0,2266.0490234375,1.99990558624268,,,,,,,0.0547024502073813,,,,25,2266.0490234375,,,
,27522309.625,,4.63027688980103,0.0716673198342323,0,2446.98298828125,1.99990558624268,,,,,,,0.0502258334158112,,,,25,2446.98298828125,,,
,27522389.469,,4.30361856460571,0.0043434739112854,0,2649.14352539063,1.99990558624268,,,,,,,0.103774161742576,,,,25,2649.14352539063,,,
,27522469.219,,4.0000119304657,0.0861455662548542,0,2876.01461914063,1.99990558624268,,,,,,,0.104842570023925,,,,25,2876.01461914063,,,
,27522996.984,,4.00000459671021,-0.117997708171606,0,2876.72651367188,1.99990558624268,,,,,,,0.162065126515844,,,,25,2876.72651367188,,,
,27523100.375,,5.98331813812256,-0.152021588087082,0,1889.39059082031,1.99990558624268,,,,,,,0.0415734213806607,,,,25,1889.39059082031,,,
,27523212.187,,8.95030723571777,-0.183149816989899,0,1320.39485839844,1.99990558624268,,,,,,,0.0104618112499748,,,,25,1320.39485839844,,,
,27523340.687,,13.388966178894,-0.112206409499049,0,959.477197265625,1.99990558624268,,,,,,,0.00832554685012663,,,,25,959.477197265625,,,
,27523669.094,,20.0267699432373,-0.168671568632126,0,710.045122070312,1.99990558624268,,,,,,,0.00846424848710619,,,,25,710.045122070312,,,
,27523828.078,,29.9526697540283,-0.293908407688141,0,526.1748828125,1.99990558624268,,,,,,,0.0480197449494518,,,,25,526.1748828125,,,
,27524020.953,,44.839909362793,-0.180978080034256,0,386.821466064453,1.99990558624268,,,,,,,0.0306879091893191,,,,25,386.821466064453,,,
,27524269.312,,67.1105044555664,-0.18242590546608,0,282.479001464844,1.99990558624268,,,,,,,0.00528360634770472,,,,25,282.479001464844,,,
,27524589.937,,100.366882629395,-0.48791689991951,0,204.975487670898,1.99990558624268,,,,,,,0.0173772474318738,,,,25,204.975487670898,,,
,27525013.844,,150.099444580078,-0.0861455662548542,0,146.804780883789,1.99990558624268,,,,,,,0.0136983496185636,,,,25,146.804780883789,,,