File: Calibration/LS_Diode_Calibration.dat
[Header]
TITLE,default name
FILEOPENTIME,1638087559.00,11/28/2021,10:19 AM
BYAPP,Resistivity,2.0,1.0
INFO,BRT Module,BRT_MODULE_NAME
INFO,3101-225 D0,BRT_HW_VERSION
INFO,BRT Module 01.03.04,BRT_SOFTWARE_VERSION
INFO,BRT282,BRT_SERIAL_NUMBER
INFO,,Sample1 Name
INFO,1,Sample1 Cross Section
INFO,1,Sample1 Length
INFO,Ohm-m,Sample1 Units
INFO,,Sample2 Name
INFO,1,Sample2 Cross Section
INFO,1,Sample2 Length
INFO,Ohm-m,Sample2 Units
INFO,,Sample3 Name
INFO,1,Sample3 Cross Section
INFO,1,Sample3 Length
INFO,Ohm,Sample3 Units
INFO,,Sample4 Name
INFO,1,Sample4 Cross Section
INFO,1,Sample4 Length
INFO,Ohm-m,Sample4 Units
FIELDGROUP,Resistivity,2,3,4,5,6,7,8,9,10,11,12,13,14,15,16,17,18,19,20,21,22,23,24,25,26,27,28,29,30,31,32,33,34,35,36,37,38,39,40,41
STARTUPGROUP,Resistivity
STARTUPAXIS,X,2,LINEAR,AUTO
STARTUPAXIS,Y1,7,LINEAR,AUTO
STARTUPAXIS,Y2,9,LINEAR,AUTO
STARTUPAXIS,Y3,11,LINEAR,AUTO
PLOT_APPEARANCE,ALL,HORZ_GRID_ON,VERT_GRID_ON,MARKERS_AND_LINES,ALL_LINES
DATATYPE,TIME,2
DATATYPE,COMMENT,1
[Data]
Comment,Time Stamp (sec),Status (code),Temperature (K),Magnetic Field (Oe),Sample Position (degrees),Bridge 1 Resistivity (Ohm-m),Bridge 1 Excitation (uA),Bridge 2 Resistivity (Ohm-m),Bridge 2 Excitation (uA),Bridge 3 Resistivity (Ohm),Bridge 3 Excitation (uA),Bridge 4 Resistivity (Ohm-m),Bridge 4 Excitation (uA),Bridge 1 Std. Dev. (Ohm-m),Bridge 2 Std. Dev. (Ohm-m),Bridge 3 Std. Dev. (Ohm),Bridge 4 Std. Dev. (Ohm-m),Number of Readings,Bridge 1 Resistance (Ohms),Bridge 2 Resistance (Ohms),Bridge 3 Resistance (Ohms),Bridge 4 Resistance (Ohms)
,28722609.047,,300.000318603516,-1.#QNAN,2.60480037539423e-009,,,,,75809.2746875,9.99890232086182,,,,,0.837932736776828,,25,,,75809.2746875,
,28724397.797,,193.512828979492,-1.#QNAN,2.60480037539423e-009,,,,,288571.965,9.99890232086182,,,,,0.765575173761328,,25,,,288571.965,
,28725673.891,,124.801788330078,-1.#QNAN,2.60480037539423e-009,,,,,296189.425,9.99890232086182,,,,,0.789342849330418,,25,,,296189.425,
,28726632.812,,80.4760995483398,-1.#QNAN,2.60480037539423e-009,,,,,300709.03625,9.99890232086182,,,,,0.680158780577649,,25,,,300709.03625,
,28727407.172,,51.8655235290527,-1.#QNAN,2.60480037539423e-009,,,,,303344.00125,9.99890232086182,,,,,0.946280496123507,,25,,,303344.00125,
,28728214.516,,33.3876054382324,-1.#QNAN,2.60480037539423e-009,,,,,304966.985,9.99890232086182,,,,,0.152643935020156,,25,,,304966.985,
,28728969.828,,21.5285071563721,-1.#QNAN,2.60480037539423e-009,,,,,309253.6625,9.99890232086182,,,,,0.481214487326078,,25,,,309253.6625,
,28729581.625,,13.8778541183472,-1.#QNAN,2.60480037539423e-009,,,,,316630.78375,9.99890232086182,,,,,0.637915860837315,,25,,,316630.78375,
,28730174.25,,8.94559116363525,-1.#QNAN,2.60480037539423e-009,,,,,324008.09875,9.99890232086182,,,,,375.309358927647,,25,,,324008.09875,
,28730741.187,,5.76842218399048,-1.#QNAN,2.60480037539423e-009,,,,,328993.2325,9.99890232086182,,,,,88.6251962764487,,25,,,328993.2325,
,28731272.547,,4.00004947662354,-1.#QNAN,2.60480037539423e-009,,,,,331975.39125,9.99890232086182,,,,,14.4476161376383,,25,,,331975.39125,
,28731799.781,,6.20506608963013,-1.#QNAN,2.60480037539423e-009,,,,,328315.95875,9.99890232086182,,,,,115.116573990455,,25,,,328315.95875,
,28732357.75,,9.62562335968018,-1.#QNAN,2.60480037539423e-009,,,,,322308.84,9.99890232086182,,,,,139.422202508668,,25,,,322308.84,
,28732917.797,,14.9319021987915,-1.#QNAN,2.60480037539423e-009,,,,,315502.99625,9.99890232086182,,,,,0.68318067876935,,25,,,315502.99625,
,28733751,,23.1631549835205,-1.#QNAN,2.60480037539423e-009,,,,,307517.94125,9.99890232086182,,,,,0.641553252795023,,25,,,307517.94125,
,28734471.922,,35.9193528747559,-1.#QNAN,2.60480037539423e-009,,,,,304731.91875,9.99890232086182,,,,,0.466449432674312,,25,,,304731.91875,
,28735327.828,,55.7504713439941,-1.#QNAN,2.60480037539423e-009,,,,,302999.63125,9.99890232086182,,,,,0.467233876251698,,25,,,302999.63125,
,28736312.984,,86.5156088256836,-1.#QNAN,2.60480037539423e-009,,,,,300134.08375,9.99890232086182,,,,,0.531422306615699,,25,,,300134.08375,
,28737501.797,,134.194893798828,-1.#QNAN,2.60480037539423e-009,,,,,295212.6875,9.99890232086182,,,,,0.838479997408816,,25,,,295212.6875,
,28739004.672,,208.151535644531,-1.#QNAN,2.60480037539423e-009,,,,,286938.575,9.99890232086182,,,,,0.926011970195479,,25,,,286938.575,
,28743082.047,,299.91072265625,-1.#QNAN,2.60480037539423e-009,,,,,75838.73625,9.99890232086182,,,,,14.0163978865379,,25,,,75838.73625,
,28743171.062,,295.641196289063,-1.#QNAN,2.60480037539423e-009,,,,,76209.1525,9.99890232086182,,,,,10.1904221070887,,25,,,76209.1525,
,28743248.531,,291.309270019531,-1.#QNAN,2.60480037539423e-009,,,,,76643.3346875,9.99890232086182,,,,,8.82023092118981,,25,,,76643.3346875,
,28743326.937,,287.631422119141,-1.#QNAN,2.60480037539423e-009,,,,,76830.9403125,9.99890232086182,,,,,11.2323964038574,,25,,,76830.9403125,
,28743405.219,,283.662713623047,-1.#QNAN,2.60480037539423e-009,,,,,76625.135,9.99890232086182,,,,,30.5119414794513,,25,,,76625.135,
,28743481.781,,279.840772705078,-1.#QNAN,2.60480037539423e-009,,,,,76910.4265625,9.99890232086182,,,,,16.2576328251161,,25,,,76910.4265625,
,28743558.641,,276.005981445313,-1.#QNAN,2.60480037539423e-009,,,,,77501.6196875,9.99890232086182,,,,,28.3976962699861,,25,,,77501.6196875,
,28743636.312,,272.123631591797,-1.#QNAN,2.60480037539423e-009,,,,,77876.1046875,9.99890232086182,,,,,16.6995042350414,,25,,,77876.1046875,
,28743714.016,,268.242021484375,-1.#QNAN,2.60480037539423e-009,,,,,78387.676875,9.99890232086182,,,,,22.2960184810933,,25,,,78387.676875,
,28743792.469,,264.321701660156,-1.#QNAN,2.60480037539423e-009,,,,,79050.9040625,9.99890232086182,,,,,16.7893331087865,,25,,,79050.9040625,
,28743870.281,,260.431417236328,-1.#QNAN,2.60480037539423e-009,,,,,79567.3540625,9.99890232086182,,,,,10.1591576742198,,25,,,79567.3540625,
,28743948.187,,256.550084228516,-1.#QNAN,2.60480037539423e-009,,,,,80526.375625,9.99890232086182,,,,,23.8071760298455,,25,,,80526.375625,
,28744025.609,,252.678500976563,-1.#QNAN,2.60480037539423e-009,,,,,81158.601875,9.99890232086182,,,,,13.1590196679742,,25,,,81158.601875,
,28744103.656,,248.780274658203,-1.#QNAN,2.60480037539423e-009,,,,,81651.568125,9.99890232086182,,,,,11.4291421339045,,25,,,81651.568125,
,28744180.812,,244.923629760742,-1.#QNAN,2.60480037539423e-009,,,,,82108.4975,9.99890232086182,,,,,10.8068700697448,,25,,,82108.4975,
,28744258.781,,241.033930053711,-1.#QNAN,2.60480037539423e-009,,,,,82558.3840625,9.99890232086182,,,,,10.4486833153559,,25,,,82558.3840625,
,28744336.266,,237.163603515625,-1.#QNAN,2.60480037539423e-009,,,,,83001.5846875,9.99890232086182,,,,,10.5534203684293,,25,,,83001.5846875,
,28744413.562,,233.30256652832,-1.#QNAN,2.60480037539423e-009,,,,,83442.4109375,9.99890232086182,,,,,10.5700146731128,,25,,,83442.4109375,
,28744491.125,,229.434526367187,-1.#QNAN,2.60480037539423e-009,,,,,83882.92,9.99890232086182,,,,,10.5963707666962,,25,,,83882.92,
,28744569.484,,225.531450195312,-1.#QNAN,2.60480037539423e-009,,,,,84326.3153125,9.99890232086182,,,,,10.5212900396244,,25,,,84326.3153125,
,28744647.406,,221.63481628418,-1.#QNAN,2.60480037539423e-009,,,,,84768.11125,9.99890232086182,,,,,10.5053946397053,,25,,,84768.11125,
,28744725.906,,217.713198242188,-1.#QNAN,2.60480037539423e-009,,,,,85212.9221875,9.99890232086182,,,,,10.4343553020226,,25,,,85212.9221875,
,28744802.922,,213.86076171875,-1.#QNAN,2.60480037539423e-009,,,,,85646.455625,9.99890232086182,,,,,10.5513297612448,,25,,,85646.455625,
,28744881.109,,209.951962890625,-1.#QNAN,2.60480037539423e-009,,,,,86086.3421875,9.99890232086182,,,,,10.7763761256759,,25,,,86086.3421875,
,28744960,,206.008627929687,-1.#QNAN,2.60480037539423e-009,,,,,86528.8503125,9.99890232086182,,,,,10.6538234420191,,25,,,86528.8503125,
,28745038,,202.11889465332,-1.#QNAN,2.60480037539423e-009,,,,,86965.543125,9.99890232086182,,,,,10.2113419491348,,25,,,86965.543125,
,28745115.656,,198.24518371582,-1.#QNAN,2.60480037539423e-009,,,,,87399.995625,9.99890232086182,,,,,10.2315738950621,,25,,,87399.995625,
,28745193.109,,194.377445678711,-1.#QNAN,2.60480037539423e-009,,,,,87890.3353125,9.99890232086182,,,,,134.446846453084,,25,,,87890.3353125,
,28745270.672,,190.514867553711,-1.#QNAN,2.60480037539423e-009,,,,,89828.8584375,9.99890232086182,,,,,6230.10571951854,,25,,,89828.8584375,
,28745348.375,,186.615925292969,-1.#QNAN,2.60480037539423e-009,,,,,88938.1625,9.99890232086182,,,,,269.375997875162,,25,,,88938.1625,
,28745425.531,,182.789479980469,-1.#QNAN,2.60480037539423e-009,,,,,289771.0175,9.99890232086182,,,,,10.2954478454262,,25,,,289771.0175,
,28745502.797,,178.915962524414,-1.#QNAN,2.60480037539423e-009,,,,,290211.7275,9.99890232086182,,,,,10.0051462283069,,25,,,290211.7275,
,28745580.234,,175.057407836914,-1.#QNAN,2.60480037539423e-009,,,,,290645.94875,9.99890232086182,,,,,10.2921200136318,,25,,,290645.94875,
,28745656.672,,171.228063964844,-1.#QNAN,2.60480037539423e-009,,,,,291075.52125,9.99890232086182,,,,,9.97119569822716,,25,,,291075.52125,
,28745734.156,,167.368313598633,-1.#QNAN,2.60480037539423e-009,,,,,291507.92875,9.99890232086182,,,,,10.2383445903706,,25,,,291507.92875,
,28745811.656,,163.516022949219,-1.#QNAN,2.60480037539423e-009,,,,,291938.9475,9.99890232086182,,,,,10.1544965433461,,25,,,291938.9475,
,28745888.922,,159.662822265625,-1.#QNAN,2.60480037539423e-009,,,,,292369.4475,9.99890232086182,,,,,10.1277680557473,,25,,,292369.4475,
,28745964.906,,155.859229736328,-1.#QNAN,2.60480037539423e-009,,,,,292791.89,9.99890232086182,,,,,10.1171339585938,,25,,,292791.89,
,28746042.609,,155.117965698242,-1.#QNAN,2.60480037539423e-009,,,,,292898.47375,9.99890232086182,,,,,0.77104665193043,,25,,,292898.47375,
,28746993.281,,299.215789794922,-1.#QNAN,2.60480037539423e-009,,,,,75822.7753125,9.99890232086182,,,,,9.36758460188637,,25,,,75822.7753125,
,28747077.844,,295.942248535156,-1.#QNAN,2.60480037539423e-009,,,,,76231.2146875,9.99890232086182,,,,,9.05235022066188,,25,,,76231.2146875,
,28747155.844,,291.59515625,-1.#QNAN,2.60480037539423e-009,,,,,76662.3196875,9.99890232086182,,,,,12.4940960483612,,25,,,76662.3196875,
,28747233.594,,287.733894042969,-1.#QNAN,2.60480037539423e-009,,,,,77122.2996875,9.99890232086182,,,,,10.6890356734047,,25,,,77122.2996875,
,28747311,,283.895471191406,-1.#QNAN,2.60480037539423e-009,,,,,77560.4240625,9.99890232086182,,,,,10.6047285239631,,25,,,77560.4240625,
,28747389.672,,279.960826416016,-1.#QNAN,2.60480037539423e-009,,,,,77968.5440625,9.99890232086182,,,,,6.71554531584444,,25,,,77968.5440625,
,28747466.047,,276.141694335937,-1.#QNAN,2.60480037539423e-009,,,,,77890.68875,9.99890232086182,,,,,7.14460967090214,,25,,,77890.68875,
,28747542.781,,272.31154296875,-1.#QNAN,2.60480037539423e-009,,,,,77904.519375,9.99890232086182,,,,,31.8018483464472,,25,,,77904.519375,
,28747620.328,,268.431372070312,-1.#QNAN,2.60480037539423e-009,,,,,78462.46625,9.99890232086182,,,,,32.6503428980068,,25,,,78462.46625,
,28747698.734,,264.513155517578,-1.#QNAN,2.60480037539423e-009,,,,,79098.389375,9.99890232086182,,,,,23.9256244813104,,25,,,79098.389375,
,28747775.844,,260.679146728516,-1.#QNAN,2.60480037539423e-009,,,,,79644.6009375,9.99890232086182,,,,,21.6200500070945,,25,,,79644.6009375,
,28747854.531,,256.738475341797,-1.#QNAN,2.60480037539423e-009,,,,,80644.1096875,9.99890232086182,,,,,12.3197105323548,,25,,,80644.1096875,
,28747930.328,,252.955472412109,-1.#QNAN,2.60480037539423e-009,,,,,81123.675,9.99890232086182,,,,,11.5338735102978,,25,,,81123.675,
,28748007.797,,249.065331420898,-1.#QNAN,2.60480037539423e-009,,,,,81587.0478125,9.99890232086182,,,,,11.2138648062623,,25,,,81587.0478125,
,28748084.187,,245.272503662109,-1.#QNAN,2.60480037539423e-009,,,,,82027.834375,9.99890232086182,,,,,10.7239040517275,,25,,,82027.834375,
,28748161.5,,241.404936523438,-1.#QNAN,2.60480037539423e-009,,,,,82471.1978125,9.99890232086182,,,,,10.5657889758758,,25,,,82471.1978125,
,28748238.406,,237.556013793945,-1.#QNAN,2.60480037539423e-009,,,,,82910.2340625,9.99890232086182,,,,,10.5511616903423,,25,,,82910.2340625,
,28748316.547,,233.66432434082,-1.#QNAN,2.60480037539423e-009,,,,,83354.5334375,9.99890232086182,,,,,10.5262100430247,,25,,,83354.5334375,
,28748395.766,,229.698985595703,-1.#QNAN,2.60480037539423e-009,,,,,83805.56875,9.99890232086182,,,,,10.5232955821096,,25,,,83805.56875,
,28748473.094,,225.841574707031,-1.#QNAN,2.60480037539423e-009,,,,,84244.1284375,9.99890232086182,,,,,10.5454062110218,,25,,,84244.1284375,
,28748550.75,,221.960654296875,-1.#QNAN,2.60480037539423e-009,,,,,84725.898125,9.99890232086182,,,,,10.0015783018093,,25,,,84725.898125,
,28748628.469,,218.076078491211,-1.#QNAN,2.60480037539423e-009,,,,,165793.8896875,9.99890232086182,,,,,97885.4035115726,,25,,,165793.8896875,
,28748705.875,,214.214425048828,-1.#QNAN,2.60480037539423e-009,,,,,286114.60625,9.99890232086182,,,,,10.4142815465992,,25,,,286114.60625,
,28748783.125,,210.359297485352,-1.#QNAN,2.60480037539423e-009,,,,,286561.50875,9.99890232086182,,,,,10.275383014455,,25,,,286561.50875,
,28748861.234,,206.459119873047,-1.#QNAN,2.60480037539423e-009,,,,,287013.4775,9.99890232086182,,,,,10.5333869192314,,25,,,287013.4775,
,28748938.687,,202.586834106445,-1.#QNAN,2.60480037539423e-009,,,,,287457.9,9.99890232086182,,,,,10.2660686797671,,25,,,287457.9,
,28749016.484,,198.707262573242,-1.#QNAN,2.60480037539423e-009,,,,,287904.79375,9.99890232086182,,,,,10.4322028509439,,25,,,287904.79375,
,28749092.516,,194.923550415039,-1.#QNAN,2.60480037539423e-009,,,,,288339.035,9.99890232086182,,,,,10.8395340608915,,25,,,288339.035,
,28749168.891,,191.116400756836,-1.#QNAN,2.60480037539423e-009,,,,,288775.615,9.99890232086182,,,,,10.5564178471521,,25,,,288775.615,
,28749247.328,,187.203791503906,-1.#QNAN,2.60480037539423e-009,,,,,289222.09375,9.99890232086182,,,,,10.3810370472213,,25,,,289222.09375,
,28749323.75,,183.377047729492,-1.#QNAN,2.60480037539423e-009,,,,,289659.23375,9.99890232086182,,,,,10.2256687085544,,25,,,289659.23375,
,28749402.531,,179.455290527344,-1.#QNAN,2.60480037539423e-009,,,,,290105.69,9.99890232086182,,,,,10.3402768668732,,25,,,290105.69,
,28749479.016,,175.61686340332,-1.#QNAN,2.60480037539423e-009,,,,,290540.28875,9.99890232086182,,,,,10.2027615866559,,25,,,290540.28875,
,28749557.797,,171.684751586914,-1.#QNAN,2.60480037539423e-009,,,,,290983.46625,9.99890232086182,,,,,10.2660694229332,,25,,,290983.46625,
,28749635.422,,167.799547119141,-1.#QNAN,2.60480037539423e-009,,,,,291422.5875,9.99890232086182,,,,,10.8312620872787,,25,,,291422.5875,
,28749712.297,,163.965415649414,-1.#QNAN,2.60480037539423e-009,,,,,291848.8225,9.99890232086182,,,,,10.1871614926506,,25,,,291848.8225,
,28749790.062,,160.090043334961,-1.#QNAN,2.60480037539423e-009,,,,,292282.29625,9.99890232086182,,,,,10.1156324215103,,25,,,292282.29625,
,28749866.828,,156.280908813477,-1.#QNAN,2.60480037539423e-009,,,,,292704.53375,9.99890232086182,,,,,10.0842890851333,,25,,,292704.53375,
,28749943.047,,152.456761474609,-1.#QNAN,2.60480037539423e-009,,,,,293130.78625,9.99890232086182,,,,,10.8333130665125,,25,,,293130.78625,
,28750019.312,,148.645328979492,-1.#QNAN,2.60480037539423e-009,,,,,293548.60375,9.99890232086182,,,,,9.72314667681343,,25,,,293548.60375,
,28750097.125,,144.760755615234,-1.#QNAN,2.60480037539423e-009,,,,,293974.94,9.99890232086182,,,,,9.98363070631512,,25,,,293974.94,
,28750174.516,,140.906296386719,-1.#QNAN,2.60480037539423e-009,,,,,294398.32125,9.99890232086182,,,,,9.93084916493644,,25,,,294398.32125,
,28750252.453,,137.019107666016,-1.#QNAN,2.60480037539423e-009,,,,,294823.16625,9.99890232086182,,,,,10.0551124133215,,25,,,294823.16625,
,28750328.781,,133.204747314453,-1.#QNAN,2.60480037539423e-009,,,,,295233.79375,9.99890232086182,,,,,9.74235665450582,,25,,,295233.79375,
,28750406.734,,129.340394897461,-1.#QNAN,2.60480037539423e-009,,,,,295649.025,9.99890232086182,,,,,9.61760635765372,,25,,,295649.025,
,28750483.219,,125.533169250488,-1.#QNAN,2.60480037539423e-009,,,,,296057.815,9.99890232086182,,,,,9.71888894720811,,25,,,296057.815,
,28750560.203,,121.661078796387,-1.#QNAN,2.60480037539423e-009,,,,,296470.05875,9.99890232086182,,,,,9.64191723637805,,25,,,296470.05875,
,28750637.641,,117.806629333496,-1.#QNAN,2.60480037539423e-009,,,,,296879.70875,9.99890232086182,,,,,9.57251489326791,,25,,,296879.70875,
,28750714.984,,113.970526123047,-1.#QNAN,2.60480037539423e-009,,,,,297287.8775,9.99890232086182,,,,,9.57059310813109,,25,,,297287.8775,
,28750790.891,,110.167856750488,-1.#QNAN,2.60480037539423e-009,,,,,297687.54875,9.99890232086182,,,,,9.74415295680969,,25,,,297687.54875,
,28750867.672,,106.33671081543,-1.#QNAN,2.60480037539423e-009,,,,,298082.95875,9.99890232086182,,,,,9.38603029492584,,25,,,298082.95875,
,28750943.359,,102.560974121094,-1.#QNAN,2.60480037539423e-009,,,,,298471.67625,9.99890232086182,,,,,9.26169321353502,,25,,,298471.67625,
,28751020.797,,98.7060491943359,-1.#QNAN,2.60480037539423e-009,,,,,298866.5375,9.99890232086182,,,,,9.20361741307885,,25,,,298866.5375,
,28751098.062,,94.8557952880859,-1.#QNAN,2.60480037539423e-009,,,,,299254.915,9.99890232086182,,,,,9.06627413330064,,25,,,299254.915,
,28751175.469,,91.0126806640625,-1.#QNAN,2.60480037539423e-009,,,,,299639.65375,9.99890232086182,,,,,9.50135231431722,,25,,,299639.65375,
,28751252.5,,87.1874432373047,-1.#QNAN,2.60480037539423e-009,,,,,300015.35375,9.99890232086182,,,,,8.94995955985539,,25,,,300015.35375,
,28751330.156,,83.2886840820313,-1.#QNAN,2.60480037539423e-009,,,,,300397.46125,9.99890232086182,,,,,9.34464405081988,,25,,,300397.46125,
,28751406.891,,79.4762789916992,-1.#QNAN,2.60480037539423e-009,,,,,300769.49625,9.99890232086182,,,,,8.44272118547243,,25,,,300769.49625,
,28751485.375,,75.5881121826172,-1.#QNAN,2.60480037539423e-009,,,,,301145.8875,9.99890232086182,,,,,8.86268040052421,,25,,,301145.8875,
,28751561.75,,71.7879321289062,-1.#QNAN,2.60480037539423e-009,,,,,301504.02625,9.99890232086182,,,,,8.56132109385405,,25,,,301504.02625,
,28751636.531,,68.0710549926758,-1.#QNAN,2.60480037539423e-009,,,,,301855.03625,9.99890232086182,,,,,8.46403524201814,,25,,,301855.03625,
,28751712.969,,64.2635733032227,-1.#QNAN,2.60480037539423e-009,,,,,302207.13875,9.99890232086182,,,,,8.6494810444828,,25,,,302207.13875,
,28751788.891,,60.4771208190918,-1.#QNAN,2.60480037539423e-009,,,,,302553.19125,9.99890232086182,,,,,8.19629552016679,,25,,,302553.19125,
,28751865.828,,56.665902557373,-1.#QNAN,2.60480037539423e-009,,,,,302896.79125,9.99890232086182,,,,,8.06436301301374,,25,,,302896.79125,
,28751942.031,,52.8681475830078,-1.#QNAN,2.60480037539423e-009,,,,,303237.765,9.99890232086182,,,,,8.14528248933422,,25,,,303237.765,
,28752019.391,,49.0236434936523,-1.#QNAN,2.60480037539423e-009,,,,,303577.7625,9.99890232086182,,,,,8.42218481283119,,25,,,303577.7625,
,28752096.703,,45.1653686523438,-1.#QNAN,2.60480037539423e-009,,,,,303914.44375,9.99890232086182,,,,,7.75107886895834,,25,,,303914.44375,
,28752173.969,,41.3335568237305,-1.#QNAN,2.60480037539423e-009,,,,,304245.86375,9.99890232086182,,,,,7.95458587239884,,25,,,304245.86375,
,28752249.609,,37.5727920532227,-1.#QNAN,2.60480037539423e-009,,,,,304575.305,9.99890232086182,,,,,7.87221901851,,25,,,304575.305,
,28752327.578,,33.725018157959,-1.#QNAN,2.60480037539423e-009,,,,,304930.43875,9.99890232086182,,,,,8.76700878950366,,25,,,304930.43875,
,28752403.359,,29.9546012878418,-1.#QNAN,2.60480037539423e-009,,,,,305322.30375,9.99890232086182,,,,,9.98209456547385,,25,,,305322.30375,
,28752479.297,,26.23692237854,-1.#QNAN,2.60480037539423e-009,,,,,305848.85,9.99890232086182,,,,,17.9202274539681,,25,,,305848.85,
,28752557.266,,22.4097541809082,-1.#QNAN,2.60480037539423e-009,,,,,308313.0775,9.99890232086182,,,,,98.2296782387566,,25,,,308313.0775,
,28752634.437,,18.7134202575684,-1.#QNAN,2.60480037539423e-009,,,,,311839.30125,9.99890232086182,,,,,79.9615532043039,,25,,,311839.30125,
,28752710.937,,15.1173045730591,-1.#QNAN,2.60480037539423e-009,,,,,315310.75125,9.99890232086182,,,,,86.824522082691,,25,,,315310.75125,
,28752787.875,,11.6885007476807,-1.#QNAN,2.60480037539423e-009,,,,,319220.1225,9.99890232086182,,,,,108.319853271655,,25,,,319220.1225,
,28752864.406,,8.93065887451172,-1.#QNAN,2.60480037539423e-009,,,,,324034.64625,9.99890232086182,,,,,382.639756405111,,25,,,324034.64625,
,28752941.312,,6.22356037139893,-1.#QNAN,2.60480037539423e-009,,,,,328295.6175,9.99890232086182,,,,,172.611920302503,,25,,,328295.6175,
,28753018.859,,3.99970860481262,-1.#QNAN,2.60480037539423e-009,,,,,331962.48875,9.99890232086182,,,,,73.5195253348983,,25,,,331962.48875,
,28753095.906,,4.00009098052979,-1.#QNAN,2.60480037539423e-009,,,,,331973.8225,9.99890232086182,,,,,11.2451161274017,,25,,,331973.8225,
,28753171.25,,4.00009882926941,-1.#QNAN,2.60480037539423e-009,,,,,331976.89125,9.99890232086182,,,,,14.40719846305,,25,,,331976.89125,
,28753248.891,,3.99439964294434,-1.#QNAN,2.60480037539423e-009,,,,,331971.9875,9.99890232086182,,,,,74.1042699533393,,25,,,331971.9875,
,28753325.016,,4.00073867797852,-1.#QNAN,2.60480037539423e-009,,,,,331981.8125,9.99890232086182,,,,,14.1664764989917,,25,,,331981.8125,
,28753402.594,,4.00003532409668,-1.#QNAN,2.60480037539423e-009,,,,,331979.79125,9.99890232086182,,,,,12.5482181575977,,25,,,331979.79125,
,28753479.125,,3.99164145469666,-1.#QNAN,2.60480037539423e-009,,,,,331988.81,9.99890232086182,,,,,15.8932841578839,,25,,,331988.81,
,28753556.828,,4.0005150604248,-1.#QNAN,2.60480037539423e-009,,,,,331974.875,9.99890232086182,,,,,11.5039294619885,,25,,,331974.875,
,28753633.359,,4.00015453338623,-1.#QNAN,2.60480037539423e-009,,,,,331958.25625,9.99890232086182,,,,,73.2568156225498,,25,,,331958.25625,
,28753708.906,,3.99989873886108,-1.#QNAN,2.60480037539423e-009,,,,,331963.70875,9.99890232086182,,,,,73.7516746201559,,25,,,331963.70875,
,28753786.875,,3.999897813797,-1.#QNAN,2.60480037539423e-009,,,,,331978.28875,9.99890232086182,,,,,10.9401789408944,,25,,,331978.28875,
,28753862.516,,3.99992735862732,-1.#QNAN,2.60480037539423e-009,,,,,331975.80625,9.99890232086182,,,,,13.535678764265,,25,,,331975.80625,
,28753938.844,,3.99991090774536,-1.#QNAN,2.60480037539423e-009,,,,,331974.4725,9.99890232086182,,,,,11.6521505965805,,25,,,331974.4725,
,28754016.453,,4.00000104904175,-1.#QNAN,2.60480037539423e-009,,,,,331976.5325,9.99890232086182,,,,,12.6947908546675,,25,,,331976.5325,
,28754092.719,,3.99998193740845,-1.#QNAN,2.60480037539423e-009,,,,,331978.13,9.99890232086182,,,,,12.700829330159,,25,,,331978.13,
,28754170.422,,4.00009874343872,-1.#QNAN,2.60480037539423e-009,,,,,331972.6075,9.99890232086182,,,,,11.9587417869504,,25,,,331972.6075,
,28754246.844,,4.00012371063232,-1.#QNAN,2.60480037539423e-009,,,,,331959.7625,9.99890232086182,,,,,73.1548517835799,,25,,,331959.7625,
,28754322.719,,4.00001377105713,-1.#QNAN,2.60480037539423e-009,,,,,331971.61375,9.99890232086182,,,,,11.8964239309025,,25,,,331971.61375,
,28754400.172,,3.99990605354309,-1.#QNAN,2.60480037539423e-009,,,,,331956.65875,9.99890232086182,,,,,72.9846557794722,,25,,,331956.65875,
,28754476.875,,4.00002029418945,-1.#QNAN,2.60480037539423e-009,,,,,331973.10125,9.99890232086182,,,,,11.2125706563061,,25,,,331973.10125,
,28754553.562,,4.00012731552124,-1.#QNAN,2.60480037539423e-009,,,,,331962.32125,9.99890232086182,,,,,73.935799147841,,25,,,331962.32125,
,28754656.766,,5.30473756790161,-1.#QNAN,2.60480037539423e-009,,,,,329717.04125,9.99890232086182,,,,,104.046472363338,,25,,,329717.04125,
,28754741.859,,8.37148708343506,-1.#QNAN,2.60480037539423e-009,,,,,325165.3375,9.99890232086182,,,,,258.230466179593,,25,,,325165.3375,
,28754819.406,,11.4647729492188,-1.#QNAN,2.60480037539423e-009,,,,,319503.95625,9.99890232086182,,,,,100.138065700055,,25,,,319503.95625,
,28754896.766,,14.7309743499756,-1.#QNAN,2.60480037539423e-009,,,,,315719.69,9.99890232086182,,,,,81.623937532716,,25,,,315719.69,
,28754973.344,,17.9359872436523,-1.#QNAN,2.60480037539423e-009,,,,,312572.38875,9.99890232086182,,,,,75.1532030023258,,25,,,312572.38875,
,28755050,,21.5922057342529,-1.#QNAN,2.60480037539423e-009,,,,,309210.58875,9.99890232086182,,,,,78.5016160543497,,25,,,309210.58875,
,28755127.25,,25.4971044158936,-1.#QNAN,2.60480037539423e-009,,,,,306036.18875,9.99890232086182,,,,,24.8643690232394,,25,,,306036.18875,
,28755204.156,,29.5025315093994,-1.#QNAN,2.60480037539423e-009,,,,,305386.18125,9.99890232086182,,,,,9.89594221088679,,25,,,305386.18125,
,28755281.859,,33.0285955810547,-1.#QNAN,2.60480037539423e-009,,,,,305011.50125,9.99890232086182,,,,,8.39501656344917,,25,,,305011.50125,
,28755359.5,,36.5700401306152,-1.#QNAN,2.60480037539423e-009,,,,,304680.43875,9.99890232086182,,,,,7.81190329752505,,25,,,304680.43875,
,28755436.641,,40.092663269043,-1.#QNAN,2.60480037539423e-009,,,,,304370.7,9.99890232086182,,,,,7.7466472633806,,25,,,304370.7,
,28755513.672,,43.6699920654297,-1.#QNAN,2.60480037539423e-009,,,,,304065.6125,9.99890232086182,,,,,7.23206821517506,,25,,,304065.6125,
,28755590.672,,47.2857131958008,-1.#QNAN,2.60480037539423e-009,,,,,303756.90375,9.99890232086182,,,,,7.34577349117122,,25,,,303756.90375,
,28755666.984,,50.9069003295898,-1.#QNAN,2.60480037539423e-009,,,,,303443.675,9.99890232086182,,,,,7.74373841365659,,25,,,303443.675,
,28755744.078,,54.559988861084,-1.#QNAN,2.60480037539423e-009,,,,,303125.72875,9.99890232086182,,,,,8.04383855028474,,25,,,303125.72875,
,28755820.625,,58.1782669067383,-1.#QNAN,2.60480037539423e-009,,,,,302805.95,9.99890232086182,,,,,7.70505510334013,,25,,,302805.95,
,28755896.922,,61.8437808227539,-1.#QNAN,2.60480037539423e-009,,,,,302480.2175,9.99890232086182,,,,,8.18185579695869,,25,,,302480.2175,
,28755973.859,,65.530680847168,-1.#QNAN,2.60480037539423e-009,,,,,302147.715,9.99890232086182,,,,,8.17780971014082,,25,,,302147.715,
,28756051.359,,69.2750894165039,-1.#QNAN,2.60480037539423e-009,,,,,301806.72125,9.99890232086182,,,,,8.29881870182155,,25,,,301806.72125,
,28756128.937,,73.0182263183594,-1.#QNAN,2.60480037539423e-009,,,,,301461.23625,9.99890232086182,,,,,8.3612384751238,,25,,,301461.23625,
,28756205,,76.6774746704102,-1.#QNAN,2.60480037539423e-009,,,,,301119.925,9.99890232086182,,,,,8.2575020637013,,25,,,301119.925,
,28756282.062,,80.4352435302734,-1.#QNAN,2.60480037539423e-009,,,,,300769.0225,9.99890232086182,,,,,8.32974450716752,,25,,,300769.0225,
,28756359.016,,84.1659692382812,-1.#QNAN,2.60480037539423e-009,,,,,300408.05,9.99890232086182,,,,,8.50205430282376,,25,,,300408.05,
,28756435.562,,87.9019094848633,-1.#QNAN,2.60480037539423e-009,,,,,300048.50625,9.99890232086182,,,,,8.63441992246502,,25,,,300048.50625,
,28756511.406,,91.6122290039063,-1.#QNAN,2.60480037539423e-009,,,,,299687.82125,9.99890232086182,,,,,9.05614674932515,,25,,,299687.82125,
,28756588.187,,95.3938424682617,-1.#QNAN,2.60480037539423e-009,,,,,299317.92625,9.99890232086182,,,,,8.82470204658137,,25,,,299317.92625,
,28756665.187,,99.1690844726563,-1.#QNAN,2.60480037539423e-009,,,,,298940.93125,9.99890232086182,,,,,9.23634526490533,,25,,,298940.93125,
,28756743.797,,103.006651306152,-1.#QNAN,2.60480037539423e-009,,,,,298558.135,9.99890232086182,,,,,9.00354358000617,,25,,,298558.135,
,28756820.656,,106.807856140137,-1.#QNAN,2.60480037539423e-009,,,,,298167.13875,9.99890232086182,,,,,9.93658481438354,,25,,,298167.13875,
,28756897.203,,110.544519042969,-1.#QNAN,2.60480037539423e-009,,,,,297786.15125,9.99890232086182,,,,,9.25075053701303,,25,,,297786.15125,
,28756975.016,,114.396176452637,-1.#QNAN,2.60480037539423e-009,,,,,297387.91625,9.99890232086182,,,,,9.71867856309155,,25,,,297387.91625,
,28757052,,118.175437011719,-1.#QNAN,2.60480037539423e-009,,,,,296991.605,9.99890232086182,,,,,9.36251691707208,,25,,,296991.605,
,28757127.234,,121.897962036133,-1.#QNAN,2.60480037539423e-009,,,,,296604.30875,9.99890232086182,,,,,9.51392588612091,,25,,,296604.30875,
,28757203.078,,125.637476196289,-1.#QNAN,2.60480037539423e-009,,,,,296207.02875,9.99890232086182,,,,,10.0709905403524,,25,,,296207.02875,
,28757280.203,,129.459939575195,-1.#QNAN,2.60480037539423e-009,,,,,295801.69125,9.99890232086182,,,,,10.1168933958218,,25,,,295801.69125,
,28757357.969,,133.316502075195,-1.#QNAN,2.60480037539423e-009,,,,,295388.67625,9.99890232086182,,,,,10.1382848922607,,25,,,295388.67625,
,28757437.172,,137.220232543945,-1.#QNAN,2.60480037539423e-009,,,,,294973.4025,9.99890232086182,,,,,9.66958872160145,,25,,,294973.4025,
,28757514.453,,141.044599609375,-1.#QNAN,2.60480037539423e-009,,,,,294559.79875,9.99890232086182,,,,,9.85197449079054,,25,,,294559.79875,
,28757590.875,,144.833402099609,-1.#QNAN,2.60480037539423e-009,,,,,294147.15625,9.99890232086182,,,,,10.1519973067572,,25,,,294147.15625,
,28757666.812,,148.558333129883,-1.#QNAN,2.60480037539423e-009,,,,,293743.43375,9.99890232086182,,,,,9.81376960461876,,25,,,293743.43375,
,28757744.016,,152.384808959961,-1.#QNAN,2.60480037539423e-009,,,,,293326.13625,9.99890232086182,,,,,9.87804201809894,,25,,,293326.13625,
,28757821.281,,156.210736694336,-1.#QNAN,2.60480037539423e-009,,,,,292900.73875,9.99890232086182,,,,,9.98456908800009,,25,,,292900.73875,
,28757898.531,,160.063480224609,-1.#QNAN,2.60480037539423e-009,,,,,292474.8025,9.99890232086182,,,,,10.2894695783651,,25,,,292474.8025,
,28757975.547,,163.866854858398,-1.#QNAN,2.60480037539423e-009,,,,,292051.56375,9.99890232086182,,,,,10.0789879717736,,25,,,292051.56375,
,28758051.969,,167.661270141602,-1.#QNAN,2.60480037539423e-009,,,,,291629.95875,9.99890232086182,,,,,10.0911147512962,,25,,,291629.95875,
,28758128.437,,171.476309204102,-1.#QNAN,2.60480037539423e-009,,,,,291203.1275,9.99890232086182,,,,,10.4263410478693,,25,,,291203.1275,
,28758204.969,,175.282491455078,-1.#QNAN,2.60480037539423e-009,,,,,290775.88625,9.99890232086182,,,,,10.5212507007767,,25,,,290775.88625,
,28758282.109,,179.112809448242,-1.#QNAN,2.60480037539423e-009,,,,,290347.18375,9.99890232086182,,,,,10.4253414400021,,25,,,290347.18375,
,28758358.687,,182.919357910156,-1.#QNAN,2.60480037539423e-009,,,,,289914.0575,9.99890232086182,,,,,10.5466999406768,,25,,,289914.0575,
,28758436.719,,186.796788330078,-1.#QNAN,2.60480037539423e-009,,,,,289475.07,9.99890232086182,,,,,10.6755246893339,,25,,,289475.07,
,28758513.266,,190.585191650391,-1.#QNAN,2.60480037539423e-009,,,,,289044.52375,9.99890232086182,,,,,10.3039374667811,,25,,,289044.52375,
,28758588.859,,194.338494262695,-1.#QNAN,2.60480037539423e-009,,,,,288614.10375,9.99890232086182,,,,,10.3164713293101,,25,,,288614.10375,
,28758664.844,,198.150252685547,-1.#QNAN,2.60480037539423e-009,,,,,288177.3125,9.99890232086182,,,,,10.9018811763656,,25,,,288177.3125,
,28758742.172,,201.991524658203,-1.#QNAN,2.60480037539423e-009,,,,,287739.94125,9.99890232086182,,,,,10.8027398484098,,25,,,287739.94125,
,28758818.687,,205.801729736328,-1.#QNAN,2.60480037539423e-009,,,,,287304.1575,9.99890232086182,,,,,10.5345696444028,,25,,,287304.1575,
,28758896.359,,209.661137695313,-1.#QNAN,2.60480037539423e-009,,,,,286859.83,9.99890232086182,,,,,10.5181466376642,,25,,,286859.83,
,28758973.156,,213.49196105957,-1.#QNAN,2.60480037539423e-009,,,,,286414.0475,9.99890232086182,,,,,10.777926344574,,25,,,286414.0475,
,28759050.344,,217.308884277344,-1.#QNAN,2.60480037539423e-009,,,,,285970.10875,9.99890232086182,,,,,10.4785351016245,,25,,,285970.10875,
,28759126.719,,221.131543579102,-1.#QNAN,2.60480037539423e-009,,,,,285525.93375,9.99890232086182,,,,,10.868896174531,,25,,,285525.93375,
,28759203.859,,224.972349243164,-1.#QNAN,2.60480037539423e-009,,,,,285076.95125,9.99890232086182,,,,,10.9370396108462,,25,,,285076.95125,
,28759279.656,,228.75022277832,-1.#QNAN,2.60480037539423e-009,,,,,284635.82375,9.99890232086182,,,,,10.856669092956,,25,,,284635.82375,
,28759357.391,,232.61414855957,-1.#QNAN,2.60480037539423e-009,,,,,284182.445,9.99890232086182,,,,,10.8304879388761,,25,,,284182.445,
,28759433.484,,236.407987060547,-1.#QNAN,2.60480037539423e-009,,,,,283735.14625,9.99890232086182,,,,,11.2983397487906,,25,,,283735.14625,
,28759511.078,,240.268556518555,-1.#QNAN,2.60480037539423e-009,,,,,283274.40125,9.99890232086182,,,,,11.0167116319101,,25,,,283274.40125,
,28759587.094,,244.039473876953,-1.#QNAN,2.60480037539423e-009,,,,,282829.15875,9.99890232086182,,,,,10.6565191956467,,25,,,282829.15875,
,28759663.984,,247.895974731445,-1.#QNAN,2.60480037539423e-009,,,,,282378.08625,9.99890232086182,,,,,10.8349707515306,,25,,,282378.08625,
,28759742.125,,251.759599609375,-1.#QNAN,2.60480037539423e-009,,,,,281928.0025,9.99890232086182,,,,,10.4848880102228,,25,,,281928.0025,
,28759817.531,,255.537267456055,-1.#QNAN,2.60480037539423e-009,,,,,281493.42375,9.99890232086182,,,,,10.378064541754,,25,,,281493.42375,
,28759894.109,,259.337515869141,-1.#QNAN,2.60480037539423e-009,,,,,93611.380625,9.99890232086182,,,,,61.9449665176827,,25,,,93611.380625,
,28759971.969,,263.223540039063,-1.#QNAN,2.60480037539423e-009,,,,,80208.675625,9.99890232086182,,,,,768.274240968489,,25,,,80208.675625,
,28760049.953,,267.097977294922,-1.#QNAN,2.60480037539423e-009,,,,,79250.44125,9.99890232086182,,,,,12.5544758311803,,25,,,79250.44125,
,28760128.172,,270.998863525391,-1.#QNAN,2.60480037539423e-009,,,,,78889.725,9.99890232086182,,,,,4.25347903850122,,25,,,78889.725,
,28760205.984,,274.867395019531,-1.#QNAN,2.60480037539423e-009,,,,,78686.0509375,9.99890232086182,,,,,10.5327523628604,,25,,,78686.0509375,
,28760282.453,,278.687744140625,-1.#QNAN,2.60480037539423e-009,,,,,78237.0521875,9.99890232086182,,,,,11.0707273762238,,25,,,78237.0521875,
,28760361.109,,282.630483398437,-1.#QNAN,2.60480037539423e-009,,,,,77777.015,9.99890232086182,,,,,10.5702283225757,,25,,,77777.015,
,28760438.578,,286.495478515625,-1.#QNAN,2.60480037539423e-009,,,,,77331.3265625,9.99890232086182,,,,,10.7453357425032,,25,,,77331.3265625,
,28760515.5,,290.322943115234,-1.#QNAN,2.60480037539423e-009,,,,,76892.0765625,9.99890232086182,,,,,10.523034805262,,25,,,76892.0765625,
,28760593.234,,294.218459472656,-1.#QNAN,2.60480037539423e-009,,,,,76451.9571875,9.99890232086182,,,,,11.4574855606418,,25,,,76451.9571875,
,28760671.578,,298.117471923828,-1.#QNAN,2.60480037539423e-009,,,,,76036.80125,9.99890232086182,,,,,19.4295378933474,,25,,,76036.80125,
,28760749.156,,299.964064941406,-1.#QNAN,2.60480037539423e-009,,,,,75766.5296875,9.99890232086182,,,,,0.842826054810239,,25,,,75766.5296875,
,28760826,,300.041619873047,-1.#QNAN,2.60480037539423e-009,,,,,75770.3675,9.99890232086182,,,,,0.375153827905681,,25,,,75770.3675,
,28760903.625,,300.026910400391,-1.#QNAN,2.60480037539423e-009,,,,,75782.163125,9.99890232086182,,,,,0.649538140167478,,25,,,75782.163125,
,28760982.812,,300.013834228516,-1.#QNAN,2.60480037539423e-009,,,,,75788.9446875,9.99890232086182,,,,,0.582533242255341,,25,,,75788.9446875,
,28761061.281,,300.007813720703,-1.#QNAN,2.60480037539423e-009,,,,,75793.4253125,9.99890232086182,,,,,0.6846504110148,,25,,,75793.4253125,
,28761138.062,,300.004991455078,-1.#QNAN,2.60480037539423e-009,,,,,75795.5434375,9.99890232086182,,,,,0.68388595875163,,25,,,75795.5434375,
,28761215.234,,300.003660888672,-1.#QNAN,2.60480037539423e-009,,,,,75797.4046875,9.99890232086182,,,,,0.68257736941271,,25,,,75797.4046875,
,28761293.484,,300.002875976563,-1.#QNAN,2.60480037539423e-009,,,,,75798.116875,9.99890232086182,,,,,0.567044864931528,,25,,,75798.116875,
,28761370.703,,300.001767578125,-1.#QNAN,2.60480037539423e-009,,,,,75798.4878125,9.99890232086182,,,,,0.887814017606389,,25,,,75798.4878125,
,28761447.016,,300.000909423828,-1.#QNAN,2.60480037539423e-009,,,,,75798.0090625,9.99890232086182,,,,,0.87378444707418,,25,,,75798.0090625,
,28761523.797,,300.000648193359,-1.#QNAN,2.60480037539423e-009,,,,,75798.81375,9.99890232086182,,,,,0.842981624416573,,25,,,75798.81375,
,28761600.641,,300.000711669922,-1.#QNAN,2.60480037539423e-009,,,,,75798.6121875,9.99890232086182,,,,,0.696047961851591,,25,,,75798.6121875,
,28761677.797,,300.000257568359,-1.#QNAN,2.60480037539423e-009,,,,,75798.7565625,9.99890232086182,,,,,0.841021612263872,,25,,,75798.7565625,
,28761755.312,,300.000432128906,-1.#QNAN,2.60480037539423e-009,,,,,75799.2615625,9.99890232086182,,,,,0.771438017792363,,25,,,75799.2615625,
,28761833.344,,300.000396728516,-1.#QNAN,2.60480037539423e-009,,,,,75799.2409375,9.99890232086182,,,,,0.593617474673542,,25,,,75799.2409375,
,28761911.094,,300.000327148438,-1.#QNAN,2.60480037539423e-009,,,,,75799.2465625,9.99890232086182,,,,,0.774038370408564,,25,,,75799.2465625,
,28761989.844,,300.000467529297,-1.#QNAN,2.60480037539423e-009,,,,,75798.7978125,9.99890232086182,,,,,0.727936133255604,,25,,,75798.7978125,
,28762066.922,,300.000163574219,-1.#QNAN,2.60480037539423e-009,,,,,75798.5934375,9.99890232086182,,,,,0.895456160758216,,25,,,75798.5934375,
,28762145.156,,300.001008300781,-1.#QNAN,2.60480037539423e-009,,,,,75798.654375,9.99890232086182,,,,,0.964338038806092,,25,,,75798.654375,
,28762223.172,,300.00099609375,-1.#QNAN,2.60480037539423e-009,,,,,75799.2290625,9.99890232086182,,,,,0.838422557514247,,25,,,75799.2290625,
,28764165.969,,298.603486328125,-1.#QNAN,2.60480037539423e-009,,,,,75983.2765625,9.99890232086182,,,,,0.878210445061678,,25,,,75983.2765625,
,28764683.312,,295.608088378906,-1.#QNAN,2.60480037539423e-009,,,,,76290.128125,9.99890232086182,,,,,1.06813752766914,,25,,,76290.128125,
,28765199.25,,292.606551513672,-1.#QNAN,2.60480037539423e-009,,,,,76551.4634375,9.99890232086182,,,,,2.98659412903346,,25,,,76551.4634375,
,28765713.25,,289.607086181641,-1.#QNAN,2.60480037539423e-009,,,,,76689.78,9.99890232086182,,,,,1.3564583192096,,25,,,76689.78,
,28766229.844,,286.605554199219,-1.#QNAN,2.60480037539423e-009,,,,,76610.9803125,9.99890232086182,,,,,21.412323138948,,25,,,76610.9803125,
,28766746.172,,283.604719238281,-1.#QNAN,2.60480037539423e-009,,,,,76979.491875,9.99890232086182,,,,,17.3108644229308,,25,,,76979.491875,
,28767261.141,,280.606627197266,-1.#QNAN,2.60480037539423e-009,,,,,77244.5825,9.99890232086182,,,,,8.79046608801232,,25,,,77244.5825,
,28767775.297,,277.604582519531,-1.#QNAN,2.60480037539423e-009,,,,,77631.2365625,9.99890232086182,,,,,25.0340025456357,,25,,,77631.2365625,
,28768291.453,,274.606086425781,-1.#QNAN,2.60480037539423e-009,,,,,77983.4296875,9.99890232086182,,,,,9.81531780628145,,25,,,77983.4296875,
,28768807.203,,271.604677734375,-1.#QNAN,2.60480037539423e-009,,,,,78370.5525,9.99890232086182,,,,,35.9492851106661,,25,,,78370.5525,
,28769323.156,,268.604733886719,-1.#QNAN,2.60480037539423e-009,,,,,78763.425625,9.99890232086182,,,,,25.1625986748252,,25,,,78763.425625,
,28769839.094,,265.604959716797,-1.#QNAN,2.60480037539423e-009,,,,,79135.9775,9.99890232086182,,,,,23.1747494211816,,25,,,79135.9775,
,28770356.078,,262.604207763672,-1.#QNAN,2.60480037539423e-009,,,,,79835.801875,9.99890232086182,,,,,2.89627381046207,,25,,,79835.801875,
,28770871.531,,259.603994140625,-1.#QNAN,2.60480037539423e-009,,,,,80360.719375,9.99890232086182,,,,,2.55075414389072,,25,,,80360.719375,
,28771385.187,,256.603843994141,-1.#QNAN,2.60480037539423e-009,,,,,80773.6696875,9.99890232086182,,,,,0.931769596025823,,25,,,80773.6696875,
,28771901,,253.604001464844,-1.#QNAN,2.60480037539423e-009,,,,,81147.7353125,9.99890232086182,,,,,0.665968370299414,,25,,,81147.7353125,
,28772414.812,,250.604586791992,-1.#QNAN,2.60480037539423e-009,,,,,81504.275,9.99890232086182,,,,,0.731187110217984,,25,,,81504.275,
,28772928.078,,247.601333007813,-1.#QNAN,2.60480037539423e-009,,,,,81853.1671875,9.99890232086182,,,,,0.64799098072133,,25,,,81853.1671875,
,28773440.984,,244.602304077148,-1.#QNAN,2.60480037539423e-009,,,,,82199.171875,9.99890232086182,,,,,0.611307064583318,,25,,,82199.171875,
,28773955.109,,241.602861328125,-1.#QNAN,2.60480037539423e-009,,,,,82541.434375,9.99890232086182,,,,,0.593791759427876,,25,,,82541.434375,
,28774471.453,,238.601015625,-1.#QNAN,2.60480037539423e-009,,,,,82884.6284375,9.99890232086182,,,,,0.567620600182863,,25,,,82884.6284375,
,28774987.828,,235.599092407227,-1.#QNAN,2.60480037539423e-009,,,,,83226.625625,9.99890232086182,,,,,0.65783644970134,,25,,,83226.625625,
,28775503.078,,232.599632568359,-1.#QNAN,2.60480037539423e-009,,,,,83568.7490625,9.99890232086182,,,,,0.769860831230483,,25,,,83568.7490625,
,28776015.484,,229.598972167969,-1.#QNAN,2.60480037539423e-009,,,,,83909.2953125,9.99890232086182,,,,,0.618330657349971,,25,,,83909.2953125,
,28776528.531,,226.601641235352,-1.#QNAN,2.60480037539423e-009,,,,,84249.021875,9.99890232086182,,,,,0.600624839949413,,25,,,84249.021875,
,28777038.687,,223.601405639648,-1.#QNAN,2.60480037539423e-009,,,,,84589.9090625,9.99890232086182,,,,,0.673109472975877,,25,,,84589.9090625,
,28777553.297,,220.598592529297,-1.#QNAN,2.60480037539423e-009,,,,,84929.0371875,9.99890232086182,,,,,0.616316168213734,,25,,,84929.0371875,
,28778067.125,,217.599639282227,-1.#QNAN,2.60480037539423e-009,,,,,85267.919375,9.99890232086182,,,,,0.653415918126079,,25,,,85267.919375,
,28778577.656,,214.597758789063,-1.#QNAN,2.60480037539423e-009,,,,,85605.9234375,9.99890232086182,,,,,0.557360588399008,,25,,,85605.9234375,
,28779090.344,,211.599860229492,-1.#QNAN,2.60480037539423e-009,,,,,85944.7353125,9.99890232086182,,,,,0.749565634512345,,25,,,85944.7353125,
,28779600.891,,208.597986450195,-1.#QNAN,2.60480037539423e-009,,,,,86281.01,9.99890232086182,,,,,0.594788296005755,,25,,,86281.01,
,28780112.687,,205.597236328125,-1.#QNAN,2.60480037539423e-009,,,,,86639.0696875,9.99890232086182,,,,,0.836654213233862,,25,,,86639.0696875,
,28780620.766,,202.597255249023,-1.#QNAN,2.60480037539423e-009,,,,,86955.81625,9.99890232086182,,,,,0.749485475161479,,25,,,86955.81625,
,28781128.609,,199.596154174805,-1.#QNAN,2.60480037539423e-009,,,,,87294.74375,9.99890232086182,,,,,0.71769703568719,,25,,,87294.74375,
,28781640.719,,196.595934448242,-1.#QNAN,2.60480037539423e-009,,,,,87635.5078125,9.99890232086182,,,,,0.489664057576443,,25,,,87635.5078125,
,28782150.719,,193.593958129883,-1.#QNAN,2.60480037539423e-009,,,,,87979.855625,9.99890232086182,,,,,0.626343618008377,,25,,,87979.855625,
,28782664.187,,190.595158081055,-1.#QNAN,2.60480037539423e-009,,,,,88420.758125,9.99890232086182,,,,,1.98781281894489,,25,,,88420.758125,
,28783168.516,,187.594271850586,-1.#QNAN,2.60480037539423e-009,,,,,289259.46375,9.99890232086182,,,,,0.730886411345198,,25,,,289259.46375,
,28783677.812,,184.595536499023,-1.#QNAN,2.60480037539423e-009,,,,,289598.1125,9.99890232086182,,,,,0.776509052486673,,25,,,289598.1125,
,28784190.391,,181.593307495117,-1.#QNAN,2.60480037539423e-009,,,,,289942.1,9.99890232086182,,,,,0.684095797784839,,25,,,289942.1,
,28784696.281,,178.591889038086,-1.#QNAN,2.60480037539423e-009,,,,,290281.82375,9.99890232086182,,,,,0.703179251379271,,25,,,290281.82375,
,28785208.094,,175.59117980957,-1.#QNAN,2.60480037539423e-009,,,,,290621.93,9.99890232086182,,,,,0.851992437338061,,25,,,290621.93,
,28785716.312,,172.590040893555,-1.#QNAN,2.60480037539423e-009,,,,,290958.59875,9.99890232086182,,,,,0.788269248545905,,25,,,290958.59875,
,28786225.891,,169.591161499023,-1.#QNAN,2.60480037539423e-009,,,,,291294.4225,9.99890232086182,,,,,0.771313766736866,,25,,,291294.4225,
,28786732,,166.58711730957,-1.#QNAN,2.60480037539423e-009,,,,,291633.09125,9.99890232086182,,,,,0.934867723869432,,25,,,291633.09125,
,28787237.844,,163.587922973633,-1.#QNAN,2.60480037539423e-009,,,,,291965.5625,9.99890232086182,,,,,1.15684370314906,,25,,,291965.5625,
,28787743.984,,160.587029418945,-1.#QNAN,2.60480037539423e-009,,,,,292298.98625,9.99890232086182,,,,,0.785214550074333,,25,,,292298.98625,
,28788249.875,,157.587456665039,-1.#QNAN,2.60480037539423e-009,,,,,292636.49125,9.99890232086182,,,,,1.20023623366467,,25,,,292636.49125,
,28788757.969,,154.58482421875,-1.#QNAN,2.60480037539423e-009,,,,,292966.3525,9.99890232086182,,,,,0.743697066787571,,25,,,292966.3525,
,28789263.672,,151.584559936523,-1.#QNAN,2.60480037539423e-009,,,,,293297.60875,9.99890232086182,,,,,0.695531917626718,,25,,,293297.60875,
,28789768.203,,148.581596679687,-1.#QNAN,2.60480037539423e-009,,,,,293626.355,9.99890232086182,,,,,0.756431973844765,,25,,,293626.355,
,28790271.156,,145.580681152344,-1.#QNAN,2.60480037539423e-009,,,,,293958.32875,9.99890232086182,,,,,0.999534498587811,,25,,,293958.32875,
,28790774.953,,142.583099975586,-1.#QNAN,2.60480037539423e-009,,,,,294285.95,9.99890232086182,,,,,0.780419480426833,,25,,,294285.95,
,28791276.781,,139.580074462891,-1.#QNAN,2.60480037539423e-009,,,,,294609.79625,9.99890232086182,,,,,0.654795169398177,,25,,,294609.79625,
,28791778.297,,136.581220092773,-1.#QNAN,2.60480037539423e-009,,,,,294937.27875,9.99890232086182,,,,,0.709250660220657,,25,,,294937.27875,
,28792279.172,,133.578912963867,-1.#QNAN,2.60480037539423e-009,,,,,295261.7575,9.99890232086182,,,,,0.648390435038951,,25,,,295261.7575,
,28792775.141,,130.576185913086,-1.#QNAN,2.60480037539423e-009,,,,,295583.6775,9.99890232086182,,,,,0.757923236110318,,25,,,295583.6775,
,28793276.219,,127.574661865234,-1.#QNAN,2.60480037539423e-009,,,,,295908.26625,9.99890232086182,,,,,1.21237314091516,,25,,,295908.26625,
,28793774.312,,124.573803710938,-1.#QNAN,2.60480037539423e-009,,,,,296223.75125,9.99890232086182,,,,,0.762029183537284,,25,,,296223.75125,
,28794270.281,,121.573640136719,-1.#QNAN,2.60480037539423e-009,,,,,296544.2775,9.99890232086182,,,,,0.673791325987922,,25,,,296544.2775,
,28794762.078,,118.571078186035,-1.#QNAN,2.60480037539423e-009,,,,,296861.7175,9.99890232086182,,,,,0.702299863061534,,25,,,296861.7175,
,28795257.812,,115.569735717773,-1.#QNAN,2.60480037539423e-009,,,,,297180.97625,9.99890232086182,,,,,0.645371138376981,,25,,,297180.97625,
,28795751.937,,112.566731567383,-1.#QNAN,2.60480037539423e-009,,,,,297492.7525,9.99890232086182,,,,,0.634918851698536,,25,,,297492.7525,
,28796243.578,,109.565124206543,-1.#QNAN,2.60480037539423e-009,,,,,297802.38125,9.99890232086182,,,,,0.646032815294626,,25,,,297802.38125,
,28796735.297,,106.564319458008,-1.#QNAN,2.60480037539423e-009,,,,,298118.44,9.99890232086182,,,,,0.658710046819729,,25,,,298118.44,
,28797227.625,,103.55863494873,-1.#QNAN,2.60480037539423e-009,,,,,298422.67875,9.99890232086182,,,,,0.657074909369881,,25,,,298422.67875,
,28797719.297,,100.556661376953,-1.#QNAN,2.60480037539423e-009,,,,,298731.225,9.99890232086182,,,,,0.944189997286861,,25,,,298731.225,
,28798213.797,,97.5534371948242,-1.#QNAN,2.60480037539423e-009,,,,,299032.73875,9.99890232086182,,,,,0.548769041526123,,25,,,299032.73875,
,28798705.109,,94.5485803222656,-1.#QNAN,2.60480037539423e-009,,,,,299333.97375,9.99890232086182,,,,,0.57565191050696,,25,,,299333.97375,
,28799197.75,,91.5425064086914,-1.#QNAN,2.60480037539423e-009,,,,,299631.94375,9.99890232086182,,,,,0.573234701026497,,25,,,299631.94375,
,28799693.078,,88.5375335693359,-1.#QNAN,2.60480037539423e-009,,,,,299929.22875,9.99890232086182,,,,,0.552592876102063,,25,,,299929.22875,
,28800024.234,,86.5353527832031,-1.#QNAN,2.60480037539423e-009,,,,,300126.7575,9.99890232086182,,,,,1.02382506974458,,25,,,300126.7575,